<?xml version="1.0"?>
<robot name="rotate_stage">
	<link name="ROOT_FRAME">
		<visual>
			<origin xyz="-1.200000000000e-02 -1.700000000000e-02 0.000000000000e+00" rpy="0.000000000000e+00 -0.000000000000e+00 0.000000000000e+00" />
			<geometry>
				<box size="4.650000000000e-02 3.400000000000e-02 2.850000000000e-02" />
			</geometry>
			<material name="mat__0">
				<color rgba="0.21 0.21 0.21 1" />
			</material>
		</visual>
		<visual>
			<origin xyz="-1.200000000000e-02 1.270000000000e-01 -2.081899558551e-18" rpy="3.141592653590e+00 -0.000000000000e+00 0.000000000000e+00" />
			<geometry>
				<box size="4.650000000000e-02 3.400000000000e-02 2.850000000000e-02" />
			</geometry>
			<material name="mat__1">
				<color rgba="0.21 0.21 0.21 1" />
			</material>
		</visual>
		<visual>
			<origin xyz="-1.200000000000e-02 5.500000000000e-02 -1.825000000000e-02" rpy="0.000000000000e+00 -0.000000000000e+00 0.000000000000e+00" />
			<geometry>
				<box size="4.650000000000e-02 1.780000000000e-01 8.000000000000e-03" />
			</geometry>
			<material name="mat__2">
				<color rgba="0.42 0.42 0.42 1" />
			</material>
		</visual>
		<collision>
			<origin xyz="-1.200000000000e-02 -1.700000000000e-02 0.000000000000e+00" rpy="0.000000000000e+00 -0.000000000000e+00 0.000000000000e+00" />
			<geometry>
				<box size="4.650000000000e-02 3.400000000000e-02 2.850000000000e-02" />
			</geometry>
			<material name="mat__3">
				<color rgba="0.21 0.21 0.21 1" />
			</material>
		</collision>
		<collision>
			<origin xyz="-1.200000000000e-02 1.270000000000e-01 -2.081899558551e-18" rpy="3.141592653590e+00 -0.000000000000e+00 0.000000000000e+00" />
			<geometry>
				<box size="4.650000000000e-02 3.400000000000e-02 2.850000000000e-02" />
			</geometry>
			<material name="mat__4">
				<color rgba="0.21 0.21 0.21 1" />
			</material>
		</collision>
		<collision>
			<origin xyz="-1.200000000000e-02 5.500000000000e-02 -1.825000000000e-02" rpy="0.000000000000e+00 -0.000000000000e+00 0.000000000000e+00" />
			<geometry>
				<box size="4.650000000000e-02 1.780000000000e-01 8.000000000000e-03" />
			</geometry>
			<material name="mat__5">
				<color rgba="0.42 0.42 0.42 1" />
			</material>
		</collision>
		<inertial>
			<!--mass value="0.078166500000000014" /-->
      <mass value="15" /> <!-- hot fix for simulation -->
			<origin xyz="-1.200000000000e-02 5.500000000000e-02 -7.729922665080e-03" />
			<inertia ixx="0.00033492298036613254" ixy="0" ixz="0" iyy="2.3667551084882516e-05" iyz="4.1108737622622212e-21" izz="0.00025523518009375011" />
		</inertial>
	</link>
	<link name="STAGE0">
		<visual>
			<origin xyz="5.500000000000e-02 5.500000000000e-02 0.000000000000e+00" rpy="0.000000000000e+00 -0.000000000000e+00 0.000000000000e+00" />
			<geometry>
				<box size="1.320000000000e-01 1.100000000000e-01 2.050000000000e-02" />
			</geometry>
			<material name="mat__6">
				<color rgba="0.28 0.56 0.56 1" />
			</material>
		</visual>
		<collision>
			<origin xyz="5.500000000000e-02 5.500000000000e-02 0.000000000000e+00" rpy="0.000000000000e+00 -0.000000000000e+00 0.000000000000e+00" />
			<geometry>
				<box size="1.320000000000e-01 1.100000000000e-01 2.050000000000e-02" />
			</geometry>
			<material name="mat__7">
				<color rgba="0.28 0.56 0.56 1" />
			</material>
		</collision>
		<inertial>
			<mass value="0.14882999999999999" />
			<origin xyz="5.500000000000e-02 5.500000000000e-02 0.000000000000e+00" />
			<inertia ixx="0.00015528240062499999" ixy="0" ixz="0" iyy="0.00022131331062500001" iyz="0" izz="0.00024406879750000002" />
		</inertial>
	</link>
	<joint name="joint0" type="revolute">
		<parent link="ROOT_FRAME" />
		<child link="STAGE0" />
		<origin xyz="0.000000000000e+00 0.000000000000e+00 0.000000000000e+00" rpy="0.000000000000e+00 -0.000000000000e+00 0.000000000000e+00" />
		<axis xyz="0.000000000000e+00 1.000000000000e+00 0.000000000000e+00" />
		<limit lower="-3.1415926535897931" upper="3.1415926535897931" velocity="31.415926535897931" effort="100" />
	</joint>
	<transmission name="joint0_trans">
		<type>transmission_interface/SimpleTransmission</type>
		<joint name="joint0">
			<hardwareInterface>hardware_interface/PositionJointInterface</hardwareInterface>
		</joint>
		<actuator name="joint0_motor">
			<hardwareInterface>hardware_interface/PositionJointInterface</hardwareInterface>
		</actuator>
	</transmission>
	<link name="STAGE1">
		<visual>
			<origin xyz="-5.500000000000e-02 5.500000000000e-02 6.735557395310e-18" rpy="-3.141592653590e+00 -0.000000000000e+00 0.000000000000e+00" />
			<geometry>
				<box size="1.320000000000e-01 1.100000000000e-01 2.050000000000e-02" />
			</geometry>
			<material name="mat__8">
				<color rgba="0.56 0.56 0.28 1" />
			</material>
		</visual>
		<collision>
			<origin xyz="-5.500000000000e-02 5.500000000000e-02 6.735557395310e-18" rpy="-3.141592653590e+00 -0.000000000000e+00 0.000000000000e+00" />
			<geometry>
				<box size="1.320000000000e-01 1.100000000000e-01 2.050000000000e-02" />
			</geometry>
			<material name="mat__9">
				<color rgba="0.56 0.56 0.28 1" />
			</material>
		</collision>
		<inertial>
			<mass value="0.14882999999999999" />
			<origin xyz="-5.500000000000e-02 5.500000000000e-02 6.735557395310e-18" />
			<inertia ixx="0.00015528240062499999" ixy="0" ixz="0" iyy="0.00022131331062500001" iyz="2.7867434164508376e-21" izz="0.00024406879750000002" />
		</inertial>
	</link>
	<joint name="joint1" type="revolute">
		<parent link="ROOT_FRAME" />
		<child link="STAGE1" />
		<origin xyz="0.000000000000e+00 1.100000000000e-01 0.000000000000e+00" rpy="3.141592653590e+00 -0.000000000000e+00 0.000000000000e+00" />
		<axis xyz="0.000000000000e+00 1.000000000000e+00 0.000000000000e+00" />
		<limit lower="-3.1415926535897931" upper="3.1415926535897931" velocity="31.415926535897931" effort="100" />
	</joint>
	<transmission name="joint1_trans">
		<type>transmission_interface/SimpleTransmission</type>
		<joint name="joint1">
			<hardwareInterface>hardware_interface/PositionJointInterface</hardwareInterface>
		</joint>
		<actuator name="joint1_motor">
			<hardwareInterface>hardware_interface/PositionJointInterface</hardwareInterface>
		</actuator>
	</transmission>
  <gazebo><!-- added manually -->
    <plugin filename="libgazebo_ros_control.so" name="control"/>
  </gazebo>
  <gazebo reference="ROOT_FRAME">
    <visual><material>
      <ambient>0.21 0.21 0.21 1</ambient>
      <diffuse>0.21 0.21 0.21 1</diffuse>
      <emmisive>0.09 0.09 0.09 1</emmisive>
    </material></visual>
  </gazebo>
  <gazebo reference="STAGE0">
    <visual><material>
      <ambient>0.28 0.56 0.56 1</ambient>
      <diffuse>0.28 0.56 0.56 1</diffuse>
      <emmisive>0.12 0.24 0.24 1</emmisive>
    </material></visual>
  </gazebo>
  <gazebo reference="STAGE1">
    <visual><material>
      <ambient>0.56 0.56 0.28 1</ambient>
      <diffuse>0.56 0.56 0.28 1</diffuse>
      <emmisive>0.24 0.24 0.12 1</emmisive>
    </material></visual>
  </gazebo>
</robot>
