<?xml version="1.0" ?>
<!-- =================================================================================== -->
<!-- |    This document was autogenerated by xacro from /hr4c_ws/src/kohaku_ros_pkgs/kohaku_description/urdf/kohaku_dualarm_sim.urdf.xacro | -->
<!-- |    EDITING THIS FILE BY HAND IS NOT RECOMMENDED                                 | -->
<!-- =================================================================================== -->
<robot name="kohaku_dualarm">
  <gazebo>
    <plugin filename="libgazebo_ros_control.so" name="control"/>
  </gazebo>
  <gazebo reference="base_link">
    <material>Gazebo/Silver</material>
    <mu1>0.2</mu1>
    <mu2>0.2</mu2>
    <selfCollide>true</selfCollide>
    <gravity>true</gravity>
  </gazebo>
  <gazebo reference="left_upperarm_link_1">
    <material>Gazebo/Silver</material>
    <mu1>0.2</mu1>
    <mu2>0.2</mu2>
    <selfCollide>true</selfCollide>
  </gazebo>
  <gazebo reference="left_forearm_link_1">
    <material>Gazebo/Silver</material>
    <mu1>0.2</mu1>
    <mu2>0.2</mu2>
    <selfCollide>true</selfCollide>
  </gazebo>
  <gazebo reference="left_wrist_yaw_link_1">
    <material>Gazebo/Silver</material>
    <mu1>0.2</mu1>
    <mu2>0.2</mu2>
    <selfCollide>true</selfCollide>
  </gazebo>
  <gazebo reference="left_wrist_pitch_link_1">
    <material>Gazebo/Silver</material>
    <mu1>0.2</mu1>
    <mu2>0.2</mu2>
    <selfCollide>true</selfCollide>
  </gazebo>
  <gazebo reference="left_hand_palm_link_1">
    <material>Gazebo/Silver</material>
    <mu1>0.2</mu1>
    <mu2>0.2</mu2>
    <selfCollide>true</selfCollide>
  </gazebo>
  <gazebo reference="left_r_finger_link_1">
    <material>Gazebo/Silver</material>
    <mu1>0.2</mu1>
    <mu2>0.2</mu2>
    <selfCollide>true</selfCollide>
  </gazebo>
  <gazebo reference="left_l_finger_link_1">
    <material>Gazebo/Silver</material>
    <mu1>0.2</mu1>
    <mu2>0.2</mu2>
    <selfCollide>true</selfCollide>
  </gazebo>
  <gazebo reference="right_upperarm_link_1">
    <material>Gazebo/Silver</material>
    <mu1>0.2</mu1>
    <mu2>0.2</mu2>
    <selfCollide>true</selfCollide>
  </gazebo>
  <gazebo reference="right_forearm_link_1">
    <material>Gazebo/Silver</material>
    <mu1>0.2</mu1>
    <mu2>0.2</mu2>
    <selfCollide>true</selfCollide>
  </gazebo>
  <gazebo reference="right_wrist_yaw_link_1">
    <material>Gazebo/Silver</material>
    <mu1>0.2</mu1>
    <mu2>0.2</mu2>
    <selfCollide>true</selfCollide>
  </gazebo>
  <gazebo reference="right_wrist_pitch_link_1">
    <material>Gazebo/Silver</material>
    <mu1>0.2</mu1>
    <mu2>0.2</mu2>
    <selfCollide>true</selfCollide>
  </gazebo>
  <gazebo reference="right_hand_palm_link_1">
    <material>Gazebo/Silver</material>
    <mu1>0.2</mu1>
    <mu2>0.2</mu2>
    <selfCollide>true</selfCollide>
  </gazebo>
  <gazebo reference="right_r_finger_link_1">
    <material>Gazebo/Silver</material>
    <mu1>0.2</mu1>
    <mu2>0.2</mu2>
    <selfCollide>true</selfCollide>
  </gazebo>
  <gazebo reference="right_l_finger_link_1">
    <material>Gazebo/Silver</material>
    <mu1>0.2</mu1>
    <mu2>0.2</mu2>
    <selfCollide>true</selfCollide>
  </gazebo>
  <gazebo reference="camera_base_1">
    <material>Gazebo/Silver</material>
    <mu1>0.2</mu1>
    <mu2>0.2</mu2>
    <selfCollide>true</selfCollide>
  </gazebo>
  <gazebo reference="camera_link_1">
    <material>Gazebo/Silver</material>
    <mu1>0.2</mu1>
    <mu2>0.2</mu2>
    <selfCollide>true</selfCollide>
  </gazebo>
  <gazebo reference="left_shoulder_link_1">
    <material>Gazebo/Silver</material>
    <mu1>0.2</mu1>
    <mu2>0.2</mu2>
    <selfCollide>true</selfCollide>
  </gazebo>
  <gazebo reference="right_shoulder_link_1">
    <material>Gazebo/Silver</material>
    <mu1>0.2</mu1>
    <mu2>0.2</mu2>
    <selfCollide>true</selfCollide>
  </gazebo>
  <gazebo reference="left_base_frame_1">
    <material>Gazebo/Silver</material>
    <mu1>0.2</mu1>
    <mu2>0.2</mu2>
    <selfCollide>true</selfCollide>
  </gazebo>
  <gazebo reference="right_base_frame_1">
    <material>Gazebo/Silver</material>
    <mu1>0.2</mu1>
    <mu2>0.2</mu2>
    <selfCollide>true</selfCollide>
  </gazebo>
  <material name="silver_default">
    <color rgba="0.700 0.700 0.700 1.000"/>
  </material>
  <material name="_">
    <color rgba="0.9607843137254902 0.9607843137254902 0.9647058823529412 1.0"/>
  </material>
  <transmission name="tran1">
    <type>transmission_interface/SimpleTransmission</type>
    <joint name="left_shoulder_yaw">
      <hardwareInterface>hardware_interface/EffortJointInterface</hardwareInterface>
    </joint>
    <actuator name="motor1">
      <hardwareInterface>hardware_interface/EffortJointInterface</hardwareInterface>
      <mechanicalReduction>1</mechanicalReduction>
    </actuator>
  </transmission>
  <transmission name="tran2">
    <type>transmission_interface/SimpleTransmission</type>
    <joint name="left_shoulder_pitch">
      <hardwareInterface>hardware_interface/EffortJointInterface</hardwareInterface>
    </joint>
    <actuator name="motor2">
      <hardwareInterface>hardware_interface/EffortJointInterface</hardwareInterface>
      <mechanicalReduction>1</mechanicalReduction>
    </actuator>
  </transmission>
  <transmission name="tran3">
    <type>transmission_interface/SimpleTransmission</type>
    <joint name="left_elbow_pitch">
      <hardwareInterface>hardware_interface/EffortJointInterface</hardwareInterface>
    </joint>
    <actuator name="motor3">
      <hardwareInterface>hardware_interface/EffortJointInterface</hardwareInterface>
      <mechanicalReduction>1</mechanicalReduction>
    </actuator>
  </transmission>
  <transmission name="tran4">
    <type>transmission_interface/SimpleTransmission</type>
    <joint name="left_wrist_yaw">
      <hardwareInterface>hardware_interface/EffortJointInterface</hardwareInterface>
    </joint>
    <actuator name="motor4">
      <hardwareInterface>hardware_interface/EffortJointInterface</hardwareInterface>
      <mechanicalReduction>1</mechanicalReduction>
    </actuator>
  </transmission>
  <transmission name="tran5">
    <type>transmission_interface/SimpleTransmission</type>
    <joint name="left_wrist_pitch">
      <hardwareInterface>hardware_interface/EffortJointInterface</hardwareInterface>
    </joint>
    <actuator name="motor5">
      <hardwareInterface>hardware_interface/EffortJointInterface</hardwareInterface>
      <mechanicalReduction>1</mechanicalReduction>
    </actuator>
  </transmission>
  <transmission name="tran6">
    <type>transmission_interface/SimpleTransmission</type>
    <joint name="left_hand_yaw">
      <hardwareInterface>hardware_interface/EffortJointInterface</hardwareInterface>
    </joint>
    <actuator name="motor6">
      <hardwareInterface>hardware_interface/EffortJointInterface</hardwareInterface>
      <mechanicalReduction>1</mechanicalReduction>
    </actuator>
  </transmission>
  <transmission name="tran7">
    <type>transmission_interface/SimpleTransmission</type>
    <joint name="left_r_finger_joint">
      <hardwareInterface>hardware_interface/EffortJointInterface</hardwareInterface>
    </joint>
    <actuator name="motor7">
      <hardwareInterface>hardware_interface/EffortJointInterface</hardwareInterface>
      <mechanicalReduction>1</mechanicalReduction>
    </actuator>
  </transmission>
  <transmission name="tran8">
    <type>transmission_interface/SimpleTransmission</type>
    <joint name="left_l_finger_joint">
      <hardwareInterface>hardware_interface/EffortJointInterface</hardwareInterface>
    </joint>
    <actuator name="motor8">
      <hardwareInterface>hardware_interface/EffortJointInterface</hardwareInterface>
      <mechanicalReduction>1</mechanicalReduction>
    </actuator>
  </transmission>
  <transmission name="tran9">
    <type>transmission_interface/SimpleTransmission</type>
    <joint name="right_shoulder_yaw">
      <hardwareInterface>hardware_interface/EffortJointInterface</hardwareInterface>
    </joint>
    <actuator name="motor9">
      <hardwareInterface>hardware_interface/EffortJointInterface</hardwareInterface>
      <mechanicalReduction>1</mechanicalReduction>
    </actuator>
  </transmission>
  <transmission name="tran10">
    <type>transmission_interface/SimpleTransmission</type>
    <joint name="right_shoulder_pitch">
      <hardwareInterface>hardware_interface/EffortJointInterface</hardwareInterface>
    </joint>
    <actuator name="motor10">
      <hardwareInterface>hardware_interface/EffortJointInterface</hardwareInterface>
      <mechanicalReduction>1</mechanicalReduction>
    </actuator>
  </transmission>
  <transmission name="tran11">
    <type>transmission_interface/SimpleTransmission</type>
    <joint name="right_elbow_pitch">
      <hardwareInterface>hardware_interface/EffortJointInterface</hardwareInterface>
    </joint>
    <actuator name="motor11">
      <hardwareInterface>hardware_interface/EffortJointInterface</hardwareInterface>
      <mechanicalReduction>1</mechanicalReduction>
    </actuator>
  </transmission>
  <transmission name="tran12">
    <type>transmission_interface/SimpleTransmission</type>
    <joint name="right_wrist_yaw">
      <hardwareInterface>hardware_interface/EffortJointInterface</hardwareInterface>
    </joint>
    <actuator name="motor12">
      <hardwareInterface>hardware_interface/EffortJointInterface</hardwareInterface>
      <mechanicalReduction>1</mechanicalReduction>
    </actuator>
  </transmission>
  <transmission name="tran13">
    <type>transmission_interface/SimpleTransmission</type>
    <joint name="right_wrist_pitch">
      <hardwareInterface>hardware_interface/EffortJointInterface</hardwareInterface>
    </joint>
    <actuator name="motor13">
      <hardwareInterface>hardware_interface/EffortJointInterface</hardwareInterface>
      <mechanicalReduction>1</mechanicalReduction>
    </actuator>
  </transmission>
  <transmission name="tran14">
    <type>transmission_interface/SimpleTransmission</type>
    <joint name="right_hand_yaw">
      <hardwareInterface>hardware_interface/EffortJointInterface</hardwareInterface>
    </joint>
    <actuator name="motor14">
      <hardwareInterface>hardware_interface/EffortJointInterface</hardwareInterface>
      <mechanicalReduction>1</mechanicalReduction>
    </actuator>
  </transmission>
  <transmission name="tran15">
    <type>transmission_interface/SimpleTransmission</type>
    <joint name="right_r_finger_joint">
      <hardwareInterface>hardware_interface/EffortJointInterface</hardwareInterface>
    </joint>
    <actuator name="motor15">
      <hardwareInterface>hardware_interface/EffortJointInterface</hardwareInterface>
      <mechanicalReduction>1</mechanicalReduction>
    </actuator>
  </transmission>
  <transmission name="tran16">
    <type>transmission_interface/SimpleTransmission</type>
    <joint name="right_l_finger_joint">
      <hardwareInterface>hardware_interface/EffortJointInterface</hardwareInterface>
    </joint>
    <actuator name="motor16">
      <hardwareInterface>hardware_interface/EffortJointInterface</hardwareInterface>
      <mechanicalReduction>1</mechanicalReduction>
    </actuator>
  </transmission>
  <link name="world"/>
  <joint name="world_to_base_link" type="fixed">
    <parent link="world"/>
    <child link="base_link"/>
  </joint>
  <link name="base_link">
    <inertial>
      <origin rpy="0 0 0" xyz="-0.15079905348722558 0.002632253893124613 0.12091351070017117"/>
      <mass value="129.89853651459157"/>
      <inertia ixx="9.979542" ixy="-0.046433" ixz="-1.764444" iyy="9.36588" iyz="-0.02707" izz="9.520271"/>
    </inertial>
    <visual>
      <origin rpy="0 0 0" xyz="0 0 0"/>
      <geometry>
        <mesh filename="package://kohaku_description/meshes/base_link.stl" scale="0.001 0.001 0.001"/>
      </geometry>
      <material name="_"/>
    </visual>
    <collision>
      <origin rpy="0 0 0" xyz="0 0 0"/>
      <geometry>
        <mesh filename="package://kohaku_description/meshes/base_link.stl" scale="0.001 0.001 0.001"/>
      </geometry>
    </collision>
  </link>
  <link name="left_upperarm_link">
    <inertial>
      <origin rpy="0 0 0" xyz="5.075907070683193e-05 0.0055551687418621265 0.06093355009099832"/>
      <mass value="1.6464184320412805"/>
      <inertia ixx="0.012435" ixy="2e-06" ixz="5e-06" iyy="0.01254" iyz="-0.000385" izz="0.000862"/>
    </inertial>
    <visual>
      <origin rpy="0 0 0" xyz="0.015 -0.16498 -0.502019"/>
      <geometry>
        <mesh filename="package://kohaku_description/meshes/left_upperarm_link_1.stl" scale="0.001 0.001 0.001"/>
      </geometry>
      <material name="_"/>
    </visual>
    <collision>
      <origin rpy="0 0 0" xyz="0.015 -0.16498 -0.502019"/>
      <geometry>
        <mesh filename="package://kohaku_description/meshes/left_upperarm_link_1.stl" scale="0.001 0.001 0.001"/>
      </geometry>
    </collision>
  </link>
  <link name="left_forearm_link">
    <inertial>
      <origin rpy="0 0 0" xyz="-0.0028629714869261927 -0.0029849490325699057 0.0665229146241868"/>
      <mass value="0.5147558278242914"/>
      <inertia ixx="0.001435" ixy="1e-06" ixz="-4.1e-05" iyy="0.001418" iyz="-5.7e-05" izz="0.000194"/>
    </inertial>
    <visual>
      <origin rpy="0 0 0" xyz="0.015 -0.164945 -0.752019"/>
      <geometry>
        <mesh filename="package://kohaku_description/meshes/left_forearm_link_1.stl" scale="0.001 0.001 0.001"/>
      </geometry>
      <material name="_"/>
    </visual>
    <collision>
      <origin rpy="0 0 0" xyz="0.015 -0.164945 -0.752019"/>
      <geometry>
        <mesh filename="package://kohaku_description/meshes/left_forearm_link_1.stl" scale="0.001 0.001 0.001"/>
      </geometry>
    </collision>
  </link>
  <link name="left_wrist_yaw_link">
    <inertial>
      <origin rpy="0 0 0" xyz="-0.0012123899494678285 0.00799629493788756 0.05493382214308451"/>
      <mass value="1.0197481013710548"/>
      <inertia ixx="0.001319" ixy="7e-06" ixz="2.4e-05" iyy="0.001172" iyz="-0.000192" izz="0.000585"/>
    </inertial>
    <visual>
      <origin rpy="0 0 0" xyz="0.015 -0.164874 -0.902019"/>
      <geometry>
        <mesh filename="package://kohaku_description/meshes/left_wrist_yaw_link_1.stl" scale="0.001 0.001 0.001"/>
      </geometry>
      <material name="_"/>
    </visual>
    <collision>
      <origin rpy="0 0 0" xyz="0.015 -0.164874 -0.902019"/>
      <geometry>
        <mesh filename="package://kohaku_description/meshes/left_wrist_yaw_link_1.stl" scale="0.001 0.001 0.001"/>
      </geometry>
    </collision>
  </link>
  <link name="left_wrist_pitch_link">
    <inertial>
      <origin rpy="0 0 0" xyz="4.65267917359076e-05 0.0005212096653225973 0.03002034855665814"/>
      <mass value="0.3895986537799301"/>
      <inertia ixx="0.000199" ixy="-0.0" ixz="1e-06" iyy="0.000188" iyz="-6e-06" izz="0.000103"/>
    </inertial>
    <visual>
      <origin rpy="0 0 0" xyz="0.015 -0.16486 -1.002019"/>
      <geometry>
        <mesh filename="package://kohaku_description/meshes/left_wrist_pitch_link_1.stl" scale="0.001 0.001 0.001"/>
      </geometry>
      <material name="_"/>
    </visual>
    <collision>
      <origin rpy="0 0 0" xyz="0.015 -0.16486 -1.002019"/>
      <geometry>
        <mesh filename="package://kohaku_description/meshes/left_wrist_pitch_link_1.stl" scale="0.001 0.001 0.001"/>
      </geometry>
    </collision>
  </link>
  <link name="left_hand_palm_link">
    <inertial>
      <origin rpy="0 0 0" xyz="0.0002318570856491807 -6.828401333128231e-05 0.017667823933595006"/>
      <mass value="0.32135536491616284"/>
      <inertia ixx="0.000221" ixy="-0.0" ixz="-0.0" iyy="5.4e-05" iyz="-0.0" izz="0.000213"/>
    </inertial>
    <visual>
      <origin rpy="0 0 0" xyz="0.015 -0.164851 -1.067019"/>
      <geometry>
        <mesh filename="package://kohaku_description/meshes/left_hand_palm_link_1.stl" scale="0.001 0.001 0.001"/>
      </geometry>
      <material name="_"/>
    </visual>
    <collision>
      <origin rpy="0 0 0" xyz="0.015 -0.164851 -1.067019"/>
      <geometry>
        <mesh filename="package://kohaku_description/meshes/left_hand_palm_link_1.stl" scale="0.001 0.001 0.001"/>
      </geometry>
    </collision>
  </link>
  <link name="left_r_finger_link">
    <inertial>
      <origin rpy="0 0 0" xyz="0.00015745354838760627 0.006862307384075728 0.03618445014614924"/>
      <mass value="0.07719980680600205"/>
      <inertia ixx="2e-05" ixy="0.0" ixz="0.0" iyy="2.8e-05" iyz="-4e-06" izz="1.5e-05"/>
    </inertial>
    <visual>
      <origin rpy="0 0 0" xyz="0.015 -0.133848 -1.089074"/>
      <geometry>
        <mesh filename="package://kohaku_description/meshes/left_r_finger_link_1.stl" scale="0.001 0.001 0.001"/>
      </geometry>
      <material name="_"/>
    </visual>
    <collision>
      <origin rpy="0 0 0" xyz="0.015 -0.133848 -1.089074"/>
      <geometry>
        <mesh filename="package://kohaku_description/meshes/left_r_finger_link_1.stl" scale="0.001 0.001 0.001"/>
      </geometry>
    </collision>
  </link>
  <link name="left_l_finger_link">
    <inertial>
      <origin rpy="0 0 0" xyz="-0.00015745364544006435 -0.006872074383145355 0.03618219144765589"/>
      <mass value="0.07719980680600244"/>
      <inertia ixx="2e-05" ixy="0.0" ixz="-0.0" iyy="2.8e-05" iyz="4e-06" izz="1.5e-05"/>
    </inertial>
    <visual>
      <origin rpy="0 0 0" xyz="0.015 -0.195848 -1.089083"/>
      <geometry>
        <mesh filename="package://kohaku_description/meshes/left_l_finger_link_1.stl" scale="0.001 0.001 0.001"/>
      </geometry>
      <material name="_"/>
    </visual>
    <collision>
      <origin rpy="0 0 0" xyz="0.015 -0.195848 -1.089083"/>
      <geometry>
        <mesh filename="package://kohaku_description/meshes/left_l_finger_link_1.stl" scale="0.001 0.001 0.001"/>
      </geometry>
    </collision>
  </link>
  <link name="right_upperarm_link">
    <inertial>
      <origin rpy="0 0 0" xyz="6.28442313096618e-05 0.006835763049751115 0.07545195310129493"/>
      <mass value="1.3298060603996433"/>
      <inertia ixx="0.010625" ixy="2e-06" ixz="6e-06" iyy="0.010715" iyz="-0.000257" izz="0.000507"/>
    </inertial>
    <visual>
      <origin rpy="0 0 0" xyz="0.015 0.165 -0.502"/>
      <geometry>
        <mesh filename="package://kohaku_description/meshes/right_upperarm_link_1.stl" scale="0.001 0.001 0.001"/>
      </geometry>
      <material name="_"/>
    </visual>
    <collision>
      <origin rpy="0 0 0" xyz="0.015 0.165 -0.502"/>
      <geometry>
        <mesh filename="package://kohaku_description/meshes/right_upperarm_link_1.stl" scale="0.001 0.001 0.001"/>
      </geometry>
    </collision>
  </link>
  <link name="right_forearm_link">
    <inertial>
      <origin rpy="0 0 0" xyz="-0.002862922182678501 -0.002976875459199807 0.06652323644658864"/>
      <mass value="0.5147646926800391"/>
      <inertia ixx="0.001435" ixy="1e-06" ixz="-4.1e-05" iyy="0.001418" iyz="-5.7e-05" izz="0.000194"/>
    </inertial>
    <visual>
      <origin rpy="0 0 0" xyz="0.015 0.165 -0.752"/>
      <geometry>
        <mesh filename="package://kohaku_description/meshes/right_forearm_link_1.stl" scale="0.001 0.001 0.001"/>
      </geometry>
      <material name="_"/>
    </visual>
    <collision>
      <origin rpy="0 0 0" xyz="0.015 0.165 -0.752"/>
      <geometry>
        <mesh filename="package://kohaku_description/meshes/right_forearm_link_1.stl" scale="0.001 0.001 0.001"/>
      </geometry>
    </collision>
  </link>
  <link name="right_wrist_yaw_link">
    <inertial>
      <origin rpy="0 0 0" xyz="-0.0012077095485982584 0.008005720369017338 0.0550085391055799"/>
      <mass value="1.0237000713299513"/>
      <inertia ixx="0.001322" ixy="7e-06" ixz="2.4e-05" iyy="0.001173" iyz="-0.000192" izz="0.000586"/>
    </inertial>
    <visual>
      <origin rpy="0 0 0" xyz="0.015 0.16505 -0.902"/>
      <geometry>
        <mesh filename="package://kohaku_description/meshes/right_wrist_yaw_link_1.stl" scale="0.001 0.001 0.001"/>
      </geometry>
      <material name="_"/>
    </visual>
    <collision>
      <origin rpy="0 0 0" xyz="0.015 0.16505 -0.902"/>
      <geometry>
        <mesh filename="package://kohaku_description/meshes/right_wrist_yaw_link_1.stl" scale="0.001 0.001 0.001"/>
      </geometry>
    </collision>
  </link>
  <link name="right_wrist_pitch_link">
    <inertial>
      <origin rpy="0 0 0" xyz="4.661107241576458e-05 0.0005260238582204257 0.030027676943425563"/>
      <mass value="0.3888941704743227"/>
      <inertia ixx="0.000199" ixy="-0.0" ixz="1e-06" iyy="0.000188" iyz="-6e-06" izz="0.000103"/>
    </inertial>
    <visual>
      <origin rpy="0 0 0" xyz="0.015 0.16505 -1.002"/>
      <geometry>
        <mesh filename="package://kohaku_description/meshes/right_wrist_pitch_link_1.stl" scale="0.001 0.001 0.001"/>
      </geometry>
      <material name="_"/>
    </visual>
    <collision>
      <origin rpy="0 0 0" xyz="0.015 0.16505 -1.002"/>
      <geometry>
        <mesh filename="package://kohaku_description/meshes/right_wrist_pitch_link_1.stl" scale="0.001 0.001 0.001"/>
      </geometry>
    </collision>
  </link>
  <link name="right_hand_palm_link">
    <inertial>
      <origin rpy="0 0 0" xyz="-2.2188362258646066e-11 -6.708764863327943e-05 0.017600327592202314"/>
      <mass value="0.3164695600213004"/>
      <inertia ixx="0.000216" ixy="-0.0" ixz="0.0" iyy="5.3e-05" iyz="-0.0" izz="0.000207"/>
    </inertial>
    <visual>
      <origin rpy="0 0 0" xyz="0.015 0.16505 -1.067"/>
      <geometry>
        <mesh filename="package://kohaku_description/meshes/right_hand_palm_link_1.stl" scale="0.001 0.001 0.001"/>
      </geometry>
      <material name="_"/>
    </visual>
    <collision>
      <origin rpy="0 0 0" xyz="0.015 0.16505 -1.067"/>
      <geometry>
        <mesh filename="package://kohaku_description/meshes/right_hand_palm_link_1.stl" scale="0.001 0.001 0.001"/>
      </geometry>
    </collision>
  </link>
  <link name="right_r_finger_link">
    <inertial>
      <origin rpy="0 0 0" xyz="0.0001574535453947555 0.006867190642168924 0.03618311934404739"/>
      <mass value="0.07719980680600211"/>
      <inertia ixx="2e-05" ixy="0.0" ixz="0.0" iyy="2.8e-05" iyz="-4e-06" izz="1.5e-05"/>
    </inertial>
    <visual>
      <origin rpy="0 0 0" xyz="0.015 0.19605 -1.08906"/>
      <geometry>
        <mesh filename="package://kohaku_description/meshes/right_r_finger_link_1.stl" scale="0.001 0.001 0.001"/>
      </geometry>
      <material name="_"/>
    </visual>
    <collision>
      <origin rpy="0 0 0" xyz="0.015 0.19605 -1.08906"/>
      <geometry>
        <mesh filename="package://kohaku_description/meshes/right_r_finger_link_1.stl" scale="0.001 0.001 0.001"/>
      </geometry>
    </collision>
  </link>
  <link name="right_l_finger_link">
    <inertial>
      <origin rpy="0 0 0" xyz="-0.0001574536484330348 -0.006867190654270244 0.036183119343653924"/>
      <mass value="0.07719980680600211"/>
      <inertia ixx="2e-05" ixy="0.0" ixz="-0.0" iyy="2.8e-05" iyz="4e-06" izz="1.5e-05"/>
    </inertial>
    <visual>
      <origin rpy="0 0 0" xyz="0.015 0.13405 -1.08906"/>
      <geometry>
        <mesh filename="package://kohaku_description/meshes/right_l_finger_link_1.stl" scale="0.001 0.001 0.001"/>
      </geometry>
      <material name="_"/>
    </visual>
    <collision>
      <origin rpy="0 0 0" xyz="0.015 0.13405 -1.08906"/>
      <geometry>
        <mesh filename="package://kohaku_description/meshes/right_l_finger_link_1.stl" scale="0.001 0.001 0.001"/>
      </geometry>
    </collision>
  </link>
  <link name="camera_base">
    <inertial>
      <origin rpy="0 0 0" xyz="0.016950029688606393 -0.00716311606080537 0.0018584699632485657"/>
      <mass value="0.14882356320498133"/>
      <inertia ixx="5.6e-05" ixy="9e-06" ixz="-2e-06" iyy="2.9e-05" iyz="9e-06" izz="6e-05"/>
    </inertial>
    <visual>
      <origin rpy="0 0 0" xyz="-0.03 -0.015 -0.795"/>
      <geometry>
        <mesh filename="package://kohaku_description/meshes/camera_base_1.stl" scale="0.001 0.001 0.001"/>
      </geometry>
      <material name="_"/>
    </visual>
    <collision>
      <origin rpy="0 0 0" xyz="-0.03 -0.015 -0.795"/>
      <geometry>
        <mesh filename="package://kohaku_description/meshes/camera_base_1.stl" scale="0.001 0.001 0.001"/>
      </geometry>
    </collision>
  </link>
  <link name="camera_jig_link">
    <inertial>
      <origin rpy="0 0 0" xyz="0.03422834270251631 0.010320547163566337 0.022530793104373115"/>
      <mass value="0.6223531709069755"/>
      <inertia ixx="0.000405" ixy="-3e-06" ixz="-6.7e-05" iyy="0.000203" iyz="-3e-06" izz="0.00041"/>
    </inertial>
    <visual>
      <origin rpy="0 0 0" xyz="-0.055 -0.0045 -0.795"/>
      <geometry>
        <mesh filename="package://kohaku_description/meshes/camera_link_1.stl" scale="0.001 0.001 0.001"/>
      </geometry>
      <material name="_"/>
    </visual>
    <collision>
      <origin rpy="0 0 0" xyz="-0.055 -0.0045 -0.795"/>
      <geometry>
        <mesh filename="package://kohaku_description/meshes/camera_link_1.stl" scale="0.001 0.001 0.001"/>
      </geometry>
    </collision>
  </link>
  <link name="left_shoulder_link">
    <inertial>
      <origin rpy="0 0 0" xyz="-0.0002483716377100001 0.002599957397357383 0.07656293547299953"/>
      <mass value="4.599230696027372"/>
      <inertia ixx="0.018029" ixy="3.5e-05" ixz="2.8e-05" iyy="0.017921" iyz="0.000417" izz="0.01062"/>
    </inertial>
    <visual>
      <origin rpy="0 0 0" xyz="0.015 -0.165 -0.360019"/>
      <geometry>
        <mesh filename="package://kohaku_description/meshes/left_shoulder_link_1.stl" scale="0.001 0.001 0.001"/>
      </geometry>
      <material name="_"/>
    </visual>
    <collision>
      <origin rpy="0 0 0" xyz="0.015 -0.165 -0.360019"/>
      <geometry>
        <mesh filename="package://kohaku_description/meshes/left_shoulder_link_1.stl" scale="0.001 0.001 0.001"/>
      </geometry>
    </collision>
  </link>
  <link name="right_shoulder_link">
    <inertial>
      <origin rpy="0 0 0" xyz="-0.00024954454442560267 0.0026120260106482773 0.07656295525588974"/>
      <mass value="4.5990809553104635"/>
      <inertia ixx="0.018029" ixy="3.5e-05" ixz="2.8e-05" iyy="0.017921" iyz="0.000416" izz="0.010619"/>
    </inertial>
    <visual>
      <origin rpy="0 0 0" xyz="0.015 0.165 -0.36"/>
      <geometry>
        <mesh filename="package://kohaku_description/meshes/right_shoulder_link_1.stl" scale="0.001 0.001 0.001"/>
      </geometry>
      <material name="_"/>
    </visual>
    <collision>
      <origin rpy="0 0 0" xyz="0.015 0.165 -0.36"/>
      <geometry>
        <mesh filename="package://kohaku_description/meshes/right_shoulder_link_1.stl" scale="0.001 0.001 0.001"/>
      </geometry>
    </collision>
  </link>
  <link name="left_base_frame">
    <inertial>
      <origin rpy="0 0 0" xyz="-0.048104095750049355 0.08571557516681824 -0.09306512049076127"/>
      <mass value="25.99551418429674"/>
      <inertia ixx="0.146903" ixy="-9.9e-05" ixz="-8.9e-05" iyy="0.101347" iyz="-0.009456" izz="0.086479"/>
    </inertial>
    <visual>
      <origin rpy="0 0 0" xyz="-0.033 -0.031 -0.36"/>
      <geometry>
        <mesh filename="package://kohaku_description/meshes/left_base_frame_1.stl" scale="0.001 0.001 0.001"/>
      </geometry>
      <material name="_"/>
    </visual>
    <collision>
      <origin rpy="0 0 0" xyz="-0.033 -0.031 -0.36"/>
      <geometry>
        <mesh filename="package://kohaku_description/meshes/left_base_frame_1.stl" scale="0.001 0.001 0.001"/>
      </geometry>
    </collision>
  </link>
  <link name="right_base_frame">
    <inertial>
      <origin rpy="0 0 0" xyz="-0.047895235127222845 -0.08570427691041646 -0.09307497415651689"/>
      <mass value="25.99675882675514"/>
      <inertia ixx="0.146909" ixy="-9.9e-05" ixz="8.9e-05" iyy="0.101349" iyz="0.00946" izz="0.086487"/>
    </inertial>
    <visual>
      <origin rpy="0 0 0" xyz="-0.033 0.031 -0.36"/>
      <geometry>
        <mesh filename="package://kohaku_description/meshes/right_base_frame_1.stl" scale="0.001 0.001 0.001"/>
      </geometry>
      <material name="_"/>
    </visual>
    <collision>
      <origin rpy="0 0 0" xyz="-0.033 0.031 -0.36"/>
      <geometry>
        <mesh filename="package://kohaku_description/meshes/right_base_frame_1.stl" scale="0.001 0.001 0.001"/>
      </geometry>
    </collision>
  </link>
  <joint name="left_arm_fix" type="fixed">
    <origin rpy="0 0 0" xyz="0.033 0.031 0.326"/>
    <parent link="base_link"/>
    <child link="left_base_frame"/>
  </joint>
  <joint name="left_shoulder_yaw" type="revolute">
    <origin rpy="0 0 0" xyz="-0.048 0.134 1.9e-05"/>
    <parent link="left_base_frame"/>
    <child link="left_shoulder_link"/>
    <axis xyz="0.0 -0.00014 1.0"/>
    <limit effort="100" lower="-0.872665" upper="2.792527" velocity="100"/>
  </joint>
  <joint name="left_shoulder_pitch" type="revolute">
    <origin rpy="0 0 0" xyz="0.0 -2e-05 0.142"/>
    <parent link="left_shoulder_link"/>
    <child link="left_upperarm_link"/>
    <axis xyz="-0.0 1.0 0.00014"/>
    <limit effort="100" lower="-0.785" upper="1.832" velocity="100"/>
  </joint>
  <joint name="left_elbow_pitch" type="revolute">
    <origin rpy="0 0 0" xyz="0.0 -3.5e-05 0.25"/>
    <parent link="left_upperarm_link"/>
    <child link="left_forearm_link"/>
    <axis xyz="-0.0 1.0 0.00014"/>
    <limit effort="100" lower="0.436" upper="2.705" velocity="100"/>
  </joint>
  <joint name="left_wrist_yaw" type="revolute">
    <origin rpy="0 0 0" xyz="0.0 -7.1e-05 0.15"/>
    <parent link="left_forearm_link"/>
    <child link="left_wrist_yaw_link"/>
    <axis xyz="0.0 -0.00014 1.0"/>
    <limit effort="100" lower="-2.094" upper="2.094" velocity="100"/>
  </joint>
  <joint name="left_wrist_pitch" type="revolute">
    <origin rpy="0 0 0" xyz="0.0 -1.4e-05 0.1"/>
    <parent link="left_wrist_yaw_link"/>
    <child link="left_wrist_pitch_link"/>
    <axis xyz="-0.0 1.0 0.00014"/>
    <limit effort="100" lower="-1.047" upper="1.047" velocity="100"/>
  </joint>
  <joint name="left_hand_yaw" type="revolute">
    <origin rpy="0 0 0" xyz="0.0 -9e-06 0.065"/>
    <parent link="left_wrist_pitch_link"/>
    <child link="left_hand_palm_link"/>
    <axis xyz="-0.0 -0.00014 1.0"/>
    <limit effort="100" lower="-2.967" upper="2.967" velocity="100"/>
  </joint>
  <joint name="left_r_finger_joint" type="revolute">
    <origin rpy="0 0 0" xyz="0.0 -0.031003 0.022055"/>
    <parent link="left_hand_palm_link"/>
    <child link="left_r_finger_link"/>
    <axis xyz="1.0 0.0 0.0"/>
    <limit effort="100" lower="-0.198" upper="1.57" velocity="100"/>
  </joint>
  <joint name="left_l_finger_joint" type="revolute">
    <origin rpy="0 0 0" xyz="0.0 0.030997 0.022064"/>
    <parent link="left_hand_palm_link"/>
    <child link="left_l_finger_link"/>
    <axis xyz="-1.0 -0.0 -0.0"/>
    <limit effort="100" lower="-0.198" upper="1.57" velocity="100"/>
  </joint>
  <joint name="right_arm_fix" type="fixed">
    <origin rpy="0 0 0" xyz="0.033 -0.031 0.326"/>
    <parent link="base_link"/>
    <child link="right_base_frame"/>
  </joint>
  <joint name="right_shoulder_yaw" type="revolute">
    <origin rpy="0 0 0" xyz="-0.048 -0.134 0.0"/>
    <parent link="right_base_frame"/>
    <child link="right_shoulder_link"/>
    <axis xyz="0.0 -0.0 1.0"/>
    <limit effort="100" lower="-2.792" upper="0.872" velocity="100"/>
  </joint>
  <joint name="right_shoulder_pitch" type="revolute">
    <origin rpy="0 0 0" xyz="0.0 0.0 0.142"/>
    <parent link="right_shoulder_link"/>
    <child link="right_upperarm_link"/>
    <axis xyz="0.0 1.0 0.0"/>
    <limit effort="100" lower="-0.785" upper="1.832" velocity="100"/>
  </joint>
  <joint name="right_elbow_pitch" type="revolute">
    <origin rpy="0 0 0" xyz="0.0 0.0 0.25"/>
    <parent link="right_upperarm_link"/>
    <child link="right_forearm_link"/>
    <axis xyz="0.0 1.0 0.0"/>
    <limit effort="100" lower="0.436" upper="2.705" velocity="100"/>
  </joint>
  <joint name="right_wrist_yaw" type="revolute">
    <origin rpy="0 0 0" xyz="0.0 -5e-05 0.15"/>
    <parent link="right_forearm_link"/>
    <child link="right_wrist_yaw_link"/>
    <axis xyz="0.0 0.0 1.0"/>
    <limit effort="100" lower="-2.094" upper="2.094" velocity="100"/>
  </joint>
  <joint name="right_wrist_pitch" type="revolute">
    <origin rpy="0 0 0" xyz="0.0 0.0 0.1"/>
    <parent link="right_wrist_yaw_link"/>
    <child link="right_wrist_pitch_link"/>
    <axis xyz="-0.0 1.0 0.0"/>
    <limit effort="100" lower="-1.047" upper="1.047" velocity="100"/>
  </joint>
  <joint name="right_hand_yaw" type="revolute">
    <origin rpy="0 0 0" xyz="0.0 0.0 0.065"/>
    <parent link="right_wrist_pitch_link"/>
    <child link="right_hand_palm_link"/>
    <axis xyz="-0.0 0.0 1.0"/>
    <limit effort="100" lower="-2.967" upper="2.967" velocity="100"/>
  </joint>
  <joint name="right_r_finger_joint" type="revolute">
    <origin rpy="0 0 0" xyz="0.0 -0.031 0.02206"/>
    <parent link="right_hand_palm_link"/>
    <child link="right_r_finger_link"/>
    <axis xyz="1.0 0.0 0.0"/>
    <limit effort="100" lower="-0.198" upper="1.57" velocity="100"/>
  </joint>
  <joint name="right_l_finger_joint" type="revolute">
    <origin rpy="0 0 0" xyz="0.0 0.031 0.02206"/>
    <parent link="right_hand_palm_link"/>
    <child link="right_l_finger_link"/>
    <axis xyz="-1.0 -0.0 -0.0"/>
    <limit effort="100" lower="-0.198" upper="1.57" velocity="100"/>
  </joint>
  <joint name="camera_base_fix" type="fixed">
    <origin rpy="0 0 0" xyz="0.03 -0.015 0.7"/>
    <parent link="base_link"/>
    <child link="camera_base"/>
  </joint>
  <joint name="camera_link_jig_fix" type="fixed">
    <origin rpy="0 1.23 0" xyz="0.025 -0.0105 0.0"/>
    <parent link="camera_base"/>
    <child link="camera_jig_link"/>
  </joint>
  <material name="camera_aluminum">
    <color rgba="0.5 0.5 0.5 1"/>
  </material>
  <!-- camera body, with origin at bottom screw mount -->
  <joint name="camera_joint" type="fixed">
    <origin rpy="0 0 0" xyz="0.039 0.012 0.013"/>
    <parent link="camera_jig_link"/>
    <child link="camera_bottom_screw_frame"/>
  </joint>
  <link name="camera_bottom_screw_frame"/>
  <joint name="camera_link_joint" type="fixed">
    <origin rpy="0 0 0" xyz="0 0.0175 0.0125"/>
    <parent link="camera_bottom_screw_frame"/>
    <child link="camera_link"/>
  </joint>
  <link name="camera_link">
    <visual>
      <origin rpy="1.5707963267948966 0 1.5707963267948966" xyz="0.0149 -0.0175 0"/>
      <geometry>
        <!-- <box size="${d435_cam_width} ${d435_cam_height} ${d435_cam_depth}"/> -->
        <mesh filename="package://realsense2_description/meshes/d435.dae"/>
        <!--<mesh filename="package://realsense2_description/meshes/d435/d435.dae" />-->
      </geometry>
      <material name="camera_aluminum"/>
    </visual>
    <collision>
      <origin rpy="0 0 0" xyz="0 -0.0175 0"/>
      <geometry>
        <box size="0.02505 0.09 0.025"/>
      </geometry>
    </collision>
    <inertial>
      <!-- The following are not reliable values, and should not be used for modeling -->
      <mass value="0.564"/>
      <origin xyz="0 0 0"/>
      <inertia ixx="0.003881243" ixy="0.0" ixz="0.0" iyy="0.000498940" iyz="0.0" izz="0.003879257"/>
    </inertial>
  </link>
  <!-- camera depth joints and links -->
  <joint name="camera_depth_joint" type="fixed">
    <origin rpy="0 0 0" xyz="0 0 0"/>
    <parent link="camera_link"/>
    <child link="camera_depth_frame"/>
  </joint>
  <link name="camera_depth_frame"/>
  <joint name="camera_depth_optical_joint" type="fixed">
    <origin rpy="-1.5707963267948966 0 -1.5707963267948966" xyz="0 0 0"/>
    <parent link="camera_depth_frame"/>
    <child link="camera_depth_optical_frame"/>
  </joint>
  <link name="camera_depth_optical_frame"/>
  <!-- camera left IR joints and links -->
  <joint name="camera_left_ir_joint" type="fixed">
    <origin rpy="0 0 0" xyz="0 0.0 0"/>
    <parent link="camera_depth_frame"/>
    <child link="camera_left_ir_frame"/>
  </joint>
  <link name="camera_left_ir_frame"/>
  <joint name="camera_left_ir_optical_joint" type="fixed">
    <origin rpy="-1.5707963267948966 0 -1.5707963267948966" xyz="0 0 0"/>
    <parent link="camera_left_ir_frame"/>
    <child link="camera_left_ir_optical_frame"/>
  </joint>
  <link name="camera_left_ir_optical_frame"/>
  <!-- camera right IR joints and links -->
  <joint name="camera_right_ir_joint" type="fixed">
    <origin rpy="0 0 0" xyz="0 -0.05 0"/>
    <parent link="camera_depth_frame"/>
    <child link="camera_right_ir_frame"/>
  </joint>
  <link name="camera_right_ir_frame"/>
  <joint name="camera_right_ir_optical_joint" type="fixed">
    <origin rpy="-1.5707963267948966 0 -1.5707963267948966" xyz="0 0 0"/>
    <parent link="camera_right_ir_frame"/>
    <child link="camera_right_ir_optical_frame"/>
  </joint>
  <link name="camera_right_ir_optical_frame"/>
  <!-- camera color joints and links -->
  <joint name="camera_color_joint" type="fixed">
    <origin rpy="0 0 0" xyz="0 0.015 0"/>
    <parent link="camera_depth_frame"/>
    <child link="camera_color_frame"/>
  </joint>
  <link name="camera_color_frame"/>
  <joint name="camera_color_optical_joint" type="fixed">
    <origin rpy="-1.5707963267948966 0 -1.5707963267948966" xyz="0 0 0"/>
    <parent link="camera_color_frame"/>
    <child link="camera_color_optical_frame"/>
  </joint>
  <link name="camera_color_optical_frame"/>
  <gazebo reference="camera_link">
    <self_collide>0</self_collide>
    <enable_wind>0</enable_wind>
    <kinematic>0</kinematic>
    <gravity>1</gravity>
    <!--<mu>1</mu>-->
    <mu2>1</mu2>
    <fdir1>0 0 0</fdir1>
    <!--<slip1>0</slip1>
      <slip2>0</slip2>-->
    <kp>1e+13</kp>
    <kd>1</kd>
    <!--<max_vel>0.01</max_vel>
      <min_depth>0</min_depth>-->
    <sensor name="cameracolor" type="camera">
      <camera name="camera">
        <horizontal_fov>1.2112585008840648</horizontal_fov>
        <image>
          <width>640</width>
          <height>480</height>
          <format>RGB_INT8</format>
        </image>
        <clip>
          <near>0.1</near>
          <far>100</far>
        </clip>
        <noise>
          <type>gaussian</type>
          <mean>0.0</mean>
          <stddev>0.007</stddev>
        </noise>
      </camera>
      <always_on>1</always_on>
      <update_rate>30</update_rate>
      <visualize>1</visualize>
    </sensor>
    <sensor name="cameraired1" type="camera">
      <camera name="camera">
        <horizontal_fov>1.4870205226991688</horizontal_fov>
        <image>
          <width>1280</width>
          <height>720</height>
          <format>L_INT8</format>
        </image>
        <clip>
          <near>0.1</near>
          <far>100</far>
        </clip>
        <noise>
          <type>gaussian</type>
          <mean>0.0</mean>
          <stddev>0.05</stddev>
        </noise>
      </camera>
      <always_on>1</always_on>
      <update_rate>90</update_rate>
      <visualize>0</visualize>
    </sensor>
    <sensor name="cameraired2" type="camera">
      <camera name="camera">
        <horizontal_fov>1.4870205226991688</horizontal_fov>
        <image>
          <width>1280</width>
          <height>720</height>
          <format>L_INT8</format>
        </image>
        <clip>
          <near>0.1</near>
          <far>100</far>
        </clip>
        <noise>
          <type>gaussian</type>
          <mean>0.0</mean>
          <stddev>0.05</stddev>
        </noise>
      </camera>
      <always_on>1</always_on>
      <update_rate>90</update_rate>
      <visualize>0</visualize>
    </sensor>
    <sensor name="cameradepth" type="depth">
      <camera name="camera">
        <horizontal_fov>1.4870205226991688</horizontal_fov>
        <image>
          <width>1280</width>
          <height>720</height>
        </image>
        <clip>
          <near>0.1</near>
          <far>100</far>
        </clip>
        <noise>
          <type>gaussian</type>
          <mean>0.0</mean>
          <stddev>0.100</stddev>
        </noise>
      </camera>
      <always_on>1</always_on>
      <update_rate>90</update_rate>
      <visualize>0</visualize>
    </sensor>
  </gazebo>
  <gazebo>
    <plugin filename="librealsense_gazebo_plugin.so" name="camera">
      <prefix>camera</prefix>
      <depthUpdateRate>30.0</depthUpdateRate>
      <colorUpdateRate>30.0</colorUpdateRate>
      <infraredUpdateRate>30.0</infraredUpdateRate>
      <depthTopicName>depth/image_raw</depthTopicName>
      <depthCameraInfoTopicName>depth/camera_info</depthCameraInfoTopicName>
      <colorTopicName>color/image_raw</colorTopicName>
      <colorCameraInfoTopicName>color/camera_info</colorCameraInfoTopicName>
      <infrared1TopicName>infra1/image_raw</infrared1TopicName>
      <infrared1CameraInfoTopicName>infra1/camera_info</infrared1CameraInfoTopicName>
      <infrared2TopicName>infra2/image_raw</infrared2TopicName>
      <infrared2CameraInfoTopicName>infra2/camera_info</infrared2CameraInfoTopicName>
      <colorOpticalframeName>camera_color_optical_frame</colorOpticalframeName>
      <depthOpticalframeName>camera_depth_optical_frame</depthOpticalframeName>
      <infrared1OpticalframeName>camera_left_ir_optical_frame</infrared1OpticalframeName>
      <infrared2OpticalframeName>camera_right_ir_optical_frame</infrared2OpticalframeName>
      <rangeMinDepth>0.2</rangeMinDepth>
      <rangeMaxDepth>10.0</rangeMaxDepth>
      <pointCloud>True</pointCloud>
      <pointCloudTopicName>depth/color/points</pointCloudTopicName>
      <pointCloudCutoff>0.25</pointCloudCutoff>
      <pointCloudCutoffMax>9.0</pointCloudCutoffMax>
    </plugin>
  </gazebo>
</robot>


